Workbook
Name _\D: #REF!
Name _\D: #REF!
Name _\D: #REF!
Name _\X: #REF!
Name _\X: #REF!
Name _\X: #REF!
Name _1공장: #REF!
Name _1공장: #REF!
Name _1공장: #REF!
Name _2: #N/A
Name _2공장: #REF!
Name _2공장: #REF!
Name _2공장: #REF!
Name _3공장: #REF!
Name _3공장: #REF!
Name _3공장: #REF!
Name \0: #N/A
Name \q: #N/A
Name \s: #N/A
Name aaaa: #REF!
Name aaaa: #REF!
Name aaaa: #REF!
Name B5471763: #REF!
Name B5471763: #REF!
Name B5471763: #REF!
Name B5471763: #REF!
Name B5471763: #REF!
Name B5471763: #REF!
Name B5471763: #REF!
Name B5471763: #REF!
Name BDCODE: #N/A
Name D: #REF!
Name D: #REF!
Name D: #REF!
Name E: #N/A
Name F_CODE: #N/A
Name F_DESC: #N/A
Name F_LVL: #N/A
Name F_PAGE: #N/A
Name F_REMK: #N/A
Name F_SEQ: #N/A
Name F_SIZE: #N/A
Name F_UNIT: #N/A
Name g: #REF!
Name g: #REF!
Name g: #REF!
Name g: #REF!
Name g: #REF!
Name g: #REF!
Name g: #REF!
Name g: #REF!
Name g: #REF!
Name ITNUM: #N/A
Name jaje1: #REF!
Name jaje1: #REF!
Name jaje1: #REF!
Name jaje1: #REF!
Name jaje1: #REF!
Name jaje1: #REF!
Name jaje1: #REF!

Sheet 작성요령
A1: 공사자금청구서작성요령
G2: 문의;본사이용현과장,이수정
A3: 1, | B3: 제출일는 매월5일까지 본사도착 할수있도록 할것
A4: 2, | B4: 글씨체는 굴림체로 할것
A5: 3, | B5: 모든 결재란은 실명서명으로 하고 결재날짜도 각각 기입할것
B6: ( 도장.사인…사용금지)
A7: 4, | B7: 전월은 공사 착공일로 부터 02월분까지로 하여 작성할것
A8: 5, | B8: 실행예산은 본사에 제출한 금액으로 작성하되 변경이 필요하면 새로 품위를 득한 후
B9: 변경할것( 미작성 현장은 필히 실행예산서 제출할고 작성할것)
A10: 6, | B10: 본사관리비는 공급가액의 3% 책정할것
A11: 7, | B11: 도급매출/실행매출 필히 작성할것
A12: 8, | B12: 공종별 진척도 필히 작성할것
A13: 9, | B13: 관기성 현황은 ~02월 까지 수령한금액 적을것(도급액으로 작성)
A14: 10, | B14: 현장관리비는 전도자금,카드사용내역서 분계하여 항목별로 작성할것
B15: (실행예산 작성시 분계하여 작성)
A16: 11, | B16: 장비비는 장비대,장비사용 유류대 구분하여 작성할것(1톤로라도 포함)
A17: 12, | B17: 보험료는 본사 경리부 문의 후 작성할것
A18: 13, | B18: 각 항목별 투입원가는 원가관리시스템에서 직접출력하여 제출할것
A19: 14, | B19: 주요자재 수불부는 현장에 맞게 항목별로 구분하여 작성할것
B20: (도급/사급 필히구분하여 작성할것)- 관급은 수량만 기재
A21: 15, | B21: 외주비 작성시 발주처 직불업체도 필히작성하고 업체별 기성내역서도 필히 제출할것
A22: 16, | B22: 장비비는 장비가동일보 필히 작성할것
A23: 17, | B23: 현장관리비 식대,유류대는 거래처 원장 필히 제출할것

Sheet 정산서
A2: 정 산 서
H3: 45670
A4: 비목별 구분 | C4: 최종 도급액 | D4: 실행예산 | E4: 실투입액 | F4: 이 윤 | G4: 도급대비(%) | H4: 실행대비(%) | I4: 비 고
A5: 직접비 | B5: 재료비 | C5: 80359734 | D5: =공사청구!H13 -> 1572500 | E5: =공사청구!X13 -> 2510000
B6: 노무비 | C6: 69914671 | D6: =공사청구!H14 -> 2206070 | E6: =공사청구!X14 -> 0
B7: 경비 | C7: 6219563 | D7: =공사청구!H15 -> 12049769 | E7: =공사청구!X15 -> 0
B8: 장비비 | D8: =공사청구!H16 -> 0 | E8: =공사청구!X16 -> 0
B9: 외주비 | D9: =공사청구!H17 -> 90855500 | E9: =공사청구!X17 -> 101505000
A10: (직접비) 소 계 | C10: =SUM(C5:C9) -> 156493968 | D10: =SUM(D5:D9) -> 106683839 | E10: =SUM(E5:E9) -> 104015000 | F10: =C10-E10 -> 52478968 | G10: =E10/C10 -> 0.66465821 | H10: =E10/D10 -> 0.97498366
A11: 간접비 | B11: 현장관리비 | C11: 8272349 | D11: =공사청구!H19 -> 1000000 | E11: =공사청구!X19 -> 1190500 | I11: 기타경비
B12: 직원급여 외 | C12: 8809248 | D12: =공사청구!H20 -> 10000000 | E12: =공사청구!X20 -> 10000000 | I12: 간접노무비
B13: 안전+품질+환경+폐기물 | C13: 5804361 | D13: =공사청구!H21 -> 5804361 | E13: =공사청구!X21 -> 5045000
A14: (간접비) 소 계 | C14: =SUM(C11:C13) -> 22885958 | D14: =SUM(D11:D13) -> 16804361 | E14: =SUM(E11:E13) -> 16235500 | F14: =C14-E14 -> 6650458 | G14: =E14/C14 -> 0.7094088 | H14: =E14/D14 -> 0.96614801
A15: 공사비 합 계 | C15: =C10+C14 -> 179379926 | D15: =D10+D14 -> 123488200 | E15: =E10+E14 -> 120250500 | F15: =C15-E15 -> 59129426 | G15: =E15/C15 -> 0.67036765 | H15: =E15/D15 -> 0.9737813
A16: 기 타 | B16: 보증수수료 | C16: 283253 | D16: =공사청구!H24 -> 283254 | E16: =공사청구!X24 -> 56790 | I16: 하도급보증 등 각종 보증수수료
B17: 수입인지 | D17: =공사청구!H25 -> 0 | E17: =공사청구!X25 -> 150000
B18: 공채매입 | D18: =공사청구!H26 -> 0 | E18: =공사청구!X26 -> 0
D19: =공사청구!H27 -> 0 | E19: =공사청구!X27 -> 0
A20: (기 타) 소 계 | C20: =SUM(C16:C19) -> 283253 | D20: =SUM(D16:D19) -> 283254 | E20: =SUM(E16:E19) -> 206790 | F20: =C20-E20 -> 76463 | G20: =E20/C20 -> 0.73005405 | H20: =E20/D20 -> 0.73005147
A21: 본 사 관 리 비 | C21: 114488 | D21: =공사청구!H29 -> 0 | E21: =공사청구!X29 -> 0 | F21: =C21-E21 -> 114488 | I21: 일반관리비
A22: 합 계 (보험제외) | C22: =C15+C20+C21 -> 179777667 | D22: =D15+D20+D21 -> 123771454 | E22: =E15+E20+E21 -> 120457290 | F22: =C22-E22 -> 59320377 | G22: =E22/C22 -> 0.67003478 | H22: =E22/D22 -> 0.97322352
A23: 공사원가(보험) | C23: =16020092-9643486 -> 6376606 | D23: =공사청구!H31 -> 11151316 | E23: =공사청구!X31 -> 11151316 | F23: =C23-E23 -> -4774710
A24: 합 계 (보험포함) | C24: =C22+C23 -> 186154273 | D24: =D22+D23-1 -> 134922769 | E24: =E22+E23-1 -> 131608605 | F24: =F22+F23 -> 54545667 | G24: =E24/C24 -> 0.70698675 | H24: =E24/D24 -> 0.97543658

Sheet 공사청구
B1: 공 사 자 금 청 구 서 (2025년 01월)
AW2: 결 재 | AX2: 담당 | BA2: 과장 | BD2: 전무 | BG2: 사장 | BK2: 회장
W3: 도급금액 | AC3: 실행금액 | AJ3: 비율 | AM3: 투입금액 | AS3: 비율
B4: 현 장 명 : 어양중 본관동 강당동 방수공사 및 기타공사 | T4: 당초 | W4: 195797760 | AC4: 139906034 | AJ4: =AC4/W4 -> 0.71454359 | AM4: =BD15 -> 131608606 | AS4: =AM4/W4 -> 0.67216605
T5: 변경 | W5: 186154273 | AC5: 130262547 | AJ5: =AC5/W5 -> 0.69975588 | AM5: 126948383 | AS5: =AM5/W5 -> 0.68195256
B6: 공사기간 : 2024.09.30~2024.11.28 | AW6: 현 장 | AX6: 공무 | BA6: 공사 | BD6: 소장 | BG6: 관 리 | BH6: 이사 | BL6: 사장
B9: 발 주 처: 익산지방교육지원청
B10: ※ 투입현황(발생) | AF10: ※ 매출 및 공정(누계) | BK10: (공급가액)
B11: 비 목 별 구 분 | H11: 실 행 예 산 (가실행) | N11: 투 입 현 황 (발 생) | AC11: 예산 대비 | AF11: 매 출 | AI11: 도 급 액 (A) | AP11: 도급매출 (B) | AW11: 실행매출 (C) | BD11: 실투입비 (D) | BJ11: 공정율 (B/A) | BM11: 손 익(D/B)
N12: 전 월 | S12: 금 월 | X12: 누 계
B13: 직 접 비 | D13: 재 료 비 | H13: 1572500 | N13: ='업체별지급현황(총괄)'!E5 -> 0 | S13: ='업체별지급현황(총괄)'!F5 -> 2510000 | X13: =SUM(N13:W13) -> 2510000 | AC13: =IF((H13=0),0,X13/H13) -> 1.5961844 | AF13: 전 월 | AI13: =W5 -> 186154273 | BD13: =N32 -> 10442290 | BJ13: =AP13/AI13 -> 0 | BM13: =IF((AP13=0),0,BD13/AP13) -> 0
D14: 노 무 비 | H14: 2206070 | N14: ='업체별지급현황(총괄)'!E6 -> 0 | S14: ='업체별지급현황(총괄)'!F6 -> 0 | X14: =SUM(N14:W14) -> 0 | AC14: =IF((H14=0),0,X14/H14) -> 0 | AF14: 금 월 | BD14: =S32 -> 121166316 | BJ14: =AP14/AI13 -> 0 | BM14: =IF((AP14=0),0,BD14/AP14) -> 0
D15: 경 비 | H15: 12049769 | N15: ='업체별지급현황(총괄)'!E7 -> 0 | S15: ='업체별지급현황(총괄)'!F7 -> 0 | X15: =SUM(N15:W15) -> 0 | AC15: =IF((H15=0),0,X15/H15) -> 0 | AF15: 누 계 | BD15: =BD13+BD14 -> 131608606 | BJ15: =AP15/AI13 -> 0 | BM15: =IF((AP15=0),0,BD15/AP15) -> 0
D16: 장 비 비 | N16: ='업체별지급현황(총괄)'!E8 -> 0 | S16: ='업체별지급현황(총괄)'!F8 -> 0 | X16: =SUM(N16:W16) -> 0 | AC16: =IF((H16=0),0,X16/H16) -> 0 | AF16: 선급금 공제후 실투입비 | BD16: =BD15-BC35 -> 131608606 | BJ16: (D/C) | BM16: =BD16/AW15 -> #DIV/0!
D17: 외 주 비 | H17: 90855500 | N17: ='업체별지급현황(총괄)'!E9 -> 0 | S17: ='업체별지급현황(총괄)'!F9 -> 101505000 | X17: =SUM(N17:W17) -> 101505000 | AC17: =IF((H17=0),0,X17/H17) -> 1.1172136 | AF17: ※ 관기성현황
B18: (직접비) 소 계 | H18: =SUM(H13:M17) -> 106683839 | N18: =SUM(N13:R17) -> 0 | S18: =SUM(S13:W17) -> 104015000 | X18: =SUM(N18:W18) -> 104015000 | AC18: =IF((H18=0),0,X18/H18) -> 0.97498366 | AF18: 구 분 | AK18: 전회까지기성 | AQ18: 금회기성액 | AW18: 누계기성액 | BC18: 기성잔액 | BJ18: 비고
B19: 간접비 | D19: 현장관리비 | H19: 1000000 | N19: ='업체별지급현황(총괄)'!E10 -> 840500 | S19: ='업체별지급현황(총괄)'!F10 -> 350000 | X19: =SUM(N19:W19) -> 1190500 | AC19: =IF((H19=0),0,X19/H19) -> 1.1905 | AF19: 금 액 | AK19: 0 | AQ19: 186154273 | AW19: =AQ19+AK19 -> 186154273 | BC19: =W5-AW19 -> 0 | BJ19: 부가세별도
D20: 직원급여 외 | H20: 10000000 | N20: ='업체별지급현황(총괄)'!E11 -> 5000000 | S20: ='업체별지급현황(총괄)'!F11 -> 5000000 | X20: =SUM(N20:W20) -> 10000000 | AC20: =IF((H20=0),0,X20/H20) -> 1 | AF20: ※ 선급금현황
D21: 안전+품질+환경+폐기물 | H21: 5804361 | N21: ='업체별지급현황(총괄)'!E12 -> 4395000 | S21: ='업체별지급현황(총괄)'!F12 -> 650000 | X21: =SUM(N21:W21) -> 5045000 | AC21: =IF((H21=0),0,X21/H21) -> 0.86917406 | AF21: 구분 | AK21: 업체명 | AQ21: 선급금지급액 | AW21: 정산금액 | BC21: 잔액 | BJ21: 비고
B22: (간접비) 소 계 | H22: =SUM(H19:M21) -> 16804361 | N22: =SUM(N19:R21) -> 10235500 | S22: =SUM(S19:W21) -> 6000000 | X22: =SUM(N22:W22) -> 16235500 | AC22: =IF((H22=0),0,X22/H22) -> 0.96614801 | AF22: 원 도 급 | BC22: =AQ22-AW22 -> 0
B23: 공사비 합 계 | H23: =H18+H22 -> 123488200 | N23: =N18+N22 -> 10235500 | S23: =S18+S22 -> 110015000 | X23: =SUM(N23:W23) -> 120250500 | AC23: =IF((H23=0),0,X23/H23) -> 0.9737813 | AF23: 하 도 급 | BC23: =AQ23-AW23 -> 0
B24: 기 타 | D24: 보증수수료 | H24: 283254 | N24: =5000+31220+20570 -> 56790 | X24: =SUM(N24:W24) -> 56790 | AC24: =IF((H24=0),0,X24/H24) -> 0.20049143 | BC24: =AQ24-AW24 -> 0
D25: 수입인지 | N25: 150000 | X25: =SUM(N25:W25) -> 150000 | AC25: =IF((H25=0),0,X25/H25) -> 0 | BC25: =AQ25-AW25 -> 0
D26: 공채매입 | X26: =SUM(N26:W26) -> 0 | AC26: =IF((H26=0),0,X26/H26) -> 0 | BC26: =AQ26-AW26 -> 0
X27: =SUM(N27:W27) -> 0 | BC27: =AQ27-AW27 -> 0
B28: (기 타) 소 계 | H28: =SUM(H24:M27) -> 283254 | N28: =SUM(N24:R27) -> 206790 | S28: =SUM(S24:W27) -> 0 | X28: =SUM(X24:AB27) -> 206790 | AC28: =IF((H28=0),0,X28/H28) -> 0.73005147
B29: 본사관리비 | H29: 0 | S29: 0 | X29: =SUM(N29:W29) -> 0 | AC29: =IF((H29=0),0,X29/H29) -> 0 | AK29: 소 계 | AQ29: =SUM(AQ23:AV28) -> 0 | AW29: =SUM(AW23:BB28) -> 0 | BC29: =SUM(BC23:BI28) -> 0
B30: 합계(보험제외) | H30: =H23+H28+H29 -> 123771454 | N30: =N28+N23+N29 -> 10442290 | S30: =S28+S23+S29 -> 110015000 | X30: =SUM(N30:W30) -> 120457290 | AC30: =IF((H30=0),0,X30/H30) -> 0.97322352 | AF30: ※내역외 투입금액
B31: 공사원가(보험) | H31: =11151316 -> 11151316 | S31: 11151316 | X31: =SUM(N31:W31) -> 11151316 | AC31: =IF((H31=0),0,X31/H31) -> 1 | AF31: 설계변경예정 및 보증금 | BC31: =AQ31-AW31 -> 0
B32: 합 계(보험포함) | H32: =H30+H31 -> 134922770 | N32: =N30 -> 10442290 | S32: =S30+S31 -> 121166316 | X32: =X30+X31 -> 131608606 | AC32: =IF((H32=0),0,X32/H32) -> 0.97543658 | BC32: =AQ32-AW32 -> 0
B33: 비율 | H33: =H32/W4 -> 0.68909251 | X33: =X32/W4 -> 0.67216605
B34: 금회 청구액 : 금회발생분-기집행금 = | O34: =S32 -> 121166316 | V34: - | AK34: 소 계 | AQ34: =SUM(AQ31:AV33) -> 0 | AW34: =SUM(AW31:BB33) -> 0 | BC34: =SUM(BC31:BI33) -> 0
N35: = | O35: =O34-W34 -> 121166316 | AF35: 합 계 | AQ35: =AQ29+AQ34 -> 0 | AW35: =AW29+AW34 -> 0 | BC35: =BC29+BC34 -> 0

Sheet 청구목록표
A1: 청구목록표 (2024년12월 2회)
A2: 공 사 명 : 어양중 본관동 강당동 방수공사 및 기타공사
A3: 공 종 | B3: 상 호 | C3: 대 표 자 | D3: 전회기성 | G3: 금회기성 | J3: 누계기성 | M3: 은행명 | N3: 계좌번호 | O3: 예금주 | P3: 입금여부 | Q3: 비 고
D4: 공 급 가 액 | E4: 부 가 세 | F4: 합 계 | G4: 공 급 가 액 | H4: 부 가 세 | I4: 합 계 | J4: 공 급 가 액 | K4: 부 가 세 | L4: 합 계
A5: 재료비 | B5: 신원EPS산업 | E5: =D5*0.1 -> 0 | F5: =D5+E5 -> 0 | G5: 2510000 | H5: =G5*0.1 -> 251000 | I5: =G5+H5 -> 2761000 | J5: =D5+G5 -> 2510000 | K5: =E5+H5 -> 251000 | L5: =J5+K5 -> 2761000 | Q5: 단열재
E6: =D6*0.1 -> 0 | F6: =D6+E6 -> 0 | H6: =G6*0.1 -> 0 | I6: =G6+H6 -> 0 | J6: =D6+G6 -> 0 | K6: =E6+H6 -> 0 | L6: =J6+K6 -> 0
H7: =G7*0.1 -> 0 | I7: =G7+H7 -> 0 | J7: =D7+G7 -> 0 | K7: =E7+H7 -> 0 | L7: =J7+K7 -> 0
H8: =G8*0.1 -> 0 | I8: =G8+H8 -> 0 | J8: =D8+G8 -> 0 | K8: =E8+H8 -> 0 | L8: =J8+K8 -> 0
H9: =G9*0.1 -> 0 | I9: =G9+H9 -> 0 | J9: =D9+G9 -> 0 | K9: =E9+H9 -> 0 | L9: =J9+K9 -> 0
H10: =G10*0.1 -> 0 | I10: =G10+H10 -> 0 | J10: =D10+G10 -> 0 | K10: =E10+H10 -> 0 | L10: =J10+K10 -> 0
J11: =D11+G11 -> 0 | K11: =E11+H11 -> 0 | L11: =J11+K11 -> 0
J12: =D12+G12 -> 0 | K12: =E12+H12 -> 0 | L12: =J12+K12 -> 0
I13: =SUM(G13:H13) -> 0 | J13: =D13+G13 -> 0 | K13: =E13+H13 -> 0 | L13: =J13+K13 -> 0
I14: =SUM(G14:H14) -> 0 | J14: =D14+G14 -> 0 | K14: =E14+H14 -> 0 | L14: =J14+K14 -> 0
I15: =SUM(G15:H15) -> 0 | J15: =D15+G15 -> 0 | K15: =E15+H15 -> 0 | L15: =J15+K15 -> 0
A16: 소 계 | D16: =SUM(D5:D15) -> 0 | E16: =SUM(E5:E15) -> 0 | F16: =SUM(F5:F15) -> 0 | G16: =SUM(G5:G15) -> 2510000 | H16: =SUM(H5:H15) -> 251000 | I16: =SUM(I5:I15) -> 2761000 | J16: =SUM(J5:J15) -> 2510000 | K16: =SUM(K5:K15) -> 251000 | L16: =SUM(L5:L15) -> 2761000
A17: 노무비 | I17: =SUM(G17:H17) -> 0 | J17: =D17+G17 -> 0 | K17: =E17+H17 -> 0 | L17: =J17+K17 -> 0
J18: =D18+G18 -> 0 | K18: =E18+H18 -> 0 | L18: =J18+K18 -> 0
J19: =D19+G19 -> 0 | K19: =E19+H19 -> 0 | L19: =J19+K19 -> 0
J20: =D20+G20 -> 0 | K20: =E20+H20 -> 0 | L20: =J20+K20 -> 0
J21: =D21+G21 -> 0 | K21: =E21+H21 -> 0 | L21: =J21+K21 -> 0
J22: =D22+G22 -> 0 | K22: =E22+H22 -> 0 | L22: =J22+K22 -> 0
J23: =D23+G23 -> 0 | K23: =E23+H23 -> 0 | L23: =J23+K23 -> 0
J24: =D24+G24 -> 0 | K24: =E24+H24 -> 0 | L24: =J24+K24 -> 0
J25: =D25+G25 -> 0 | K25: =E25+H25 -> 0 | L25: =J25+K25 -> 0
A26: 소 계 | D26: =SUM(D17:D25) -> 0 | E26: =SUM(E17:E25) -> 0 | F26: =SUM(F17:F25) -> 0 | G26: =SUM(G17:G25) -> 0 | H26: =SUM(H17:H25) -> 0 | I26: =SUM(I17:I25) -> 0 | J26: =SUM(J17:J25) -> 0 | K26: =SUM(K17:K25) -> 0 | L26: =SUM(L17:L25) -> 0
A27: 경비 | E27: =D27*0.1 -> 0 | F27: =D27+E27 -> 0 | H27: =G27*0.1 -> 0 | I27: =G27+H27 -> 0 | J27: =D27+G27 -> 0 | K27: =E27+H27 -> 0 | L27: =J27+K27 -> 0
E28: =D28*0.1 -> 0 | F28: =D28+E28 -> 0 | H28: =G28*0.1 -> 0 | I28: =G28+H28 -> 0 | J28: =D28+G28 -> 0 | K28: =E28+H28 -> 0 | L28: =J28+K28 -> 0
E29: =D29*0.1 -> 0 | F29: =D29+E29 -> 0 | H29: =G29*0.1 -> 0 | I29: =G29+H29 -> 0 | J29: =D29+G29 -> 0 | K29: =E29+H29 -> 0 | L29: =J29+K29 -> 0
E30: =D30*0.1 -> 0 | F30: =D30+E30 -> 0 | H30: =G30*0.1 -> 0 | I30: =G30+H30 -> 0 | J30: =D30+G30 -> 0 | K30: =E30+H30 -> 0 | L30: =J30+K30 -> 0
E31: =D31*0.1 -> 0 | F31: =D31+E31 -> 0 | H31: =G31*0.1 -> 0 | I31: =G31+H31 -> 0 | J31: =D31+G31 -> 0 | K31: =E31+H31 -> 0 | L31: =J31+K31 -> 0
E32: =D32*0.1 -> 0 | F32: =D32+E32 -> 0 | H32: =G32*0.1 -> 0 | I32: =G32+H32 -> 0 | J32: =D32+G32 -> 0 | K32: =E32+H32 -> 0 | L32: =J32+K32 -> 0
E33: =D33*0.1 -> 0 | F33: =D33+E33 -> 0 | H33: =G33*0.1 -> 0 | I33: =G33+H33 -> 0 | J33: =D33+G33 -> 0 | K33: =E33+H33 -> 0 | L33: =J33+K33 -> 0
E34: =D34*0.1 -> 0 | F34: =D34+E34 -> 0 | H34: =G34*0.1 -> 0 | I34: =G34+H34 -> 0 | J34: =D34+G34 -> 0 | K34: =E34+H34 -> 0 | L34: =J34+K34 -> 0
E35: =D35*0.1 -> 0 | F35: =D35+E35 -> 0 | J35: =D35+G35 -> 0 | K35: =E35+H35 -> 0 | L35: =J35+K35 -> 0
A36: 소 계 | D36: =SUM(D27:D35) -> 0 | E36: =SUM(E27:E35) -> 0 | F36: =SUM(F27:F35) -> 0 | G36: =SUM(G27:G35) -> 0 | H36: =SUM(H27:H35) -> 0 | I36: =SUM(I27:I35) -> 0 | J36: =SUM(J27:J35) -> 0 | K36: =SUM(K27:K35) -> 0 | L36: =SUM(L27:L35) -> 0
A37: 장비비 | E37: =D37*0.1 -> 0 | F37: =D37+E37 -> 0 | H37: =G37*0.1 -> 0 | I37: =G37+H37 -> 0 | J37: =D37+G37 -> 0 | K37: =E37+H37 -> 0 | L37: =J37+K37 -> 0
E38: =D38*0.1 -> 0 | F38: =D38+E38 -> 0 | H38: =G38*0.1 -> 0 | I38: =G38+H38 -> 0 | J38: =D38+G38 -> 0 | K38: =E38+H38 -> 0 | L38: =J38+K38 -> 0
E39: =D39*0.1 -> 0 | F39: =D39+E39 -> 0 | H39: =G39*0.1 -> 0 | I39: =G39+H39 -> 0 | J39: =D39+G39 -> 0 | K39: =E39+H39 -> 0 | L39: =J39+K39 -> 0
E40: =D40*0.1 -> 0 | F40: =D40+E40 -> 0 | H40: =G40*0.1 -> 0 | I40: =G40+H40 -> 0 | J40: =D40+G40 -> 0 | K40: =E40+H40 -> 0 | L40: =J40+K40 -> 0
...

Sheet 자금청구
A2: 자금청구총괄집계표 ( 09월)
A3: 현 장 명 : 충북혁신도시 오피스텔 신축공사
A4: 공사기간 : 2014.05.20 ~ 2015.06.30
A8: 순번 | B8: 공종(업체)명 | D8: 실 행 예 산 | E8: 전회누계 | F8: 금월발생 | G8: 기 집행금액 | J8: 금회청구 | K8: 누 계 | L8: 비 고
G9: 본사집행 | H9: 현장경비 | I9: 계
A10: 직 접 공 사 비 | B10: 재 료 비 | F10: =F11 -> 0 | J10: =F10 -> 0 | K10: =E10+F10 -> 0 | M10: =J10*1.1 -> 0
B11: 원재료(사급+골재) | F11: ='업체별지급현황(총괄)'!E5 -> 0 | J11: =F11 -> 0 | K11: =E11+F11 -> 0
B12: 노 무 비 | F12: =F13 -> 0 | J12: =F12 -> 0 | K12: =E12+F12 -> 0 | M12: =F12+145670 -> 145670
B13: 직영노무비 | F13: ='업체별지급현황(총괄)'!E6 -> 0 | J13: =F13 -> 0 | K13: =E13+F13 -> 0
B14: 경 비 | F14: =F15+F16+F17 -> 0
B15: 폐기물처리비 | F15: ='업체별지급현황(총괄)'!E7 -> 0
B18: 장 비 비 | F18: =F19 -> 0 | J18: =J19 -> #REF! | K18: =E18+F18 -> 0 | M18: =F18*1.1 -> 0
B19: 장 비 비 | F19: ='업체별지급현황(총괄)'!E8 -> 0 | J19: =#REF! -> #REF! | K19: =E19+F19 -> 0
B20: 유 류 대
B21: 기 타
B22: 외주공사비 | F22: ='자금청구내역(을)'!E44 -> #REF! | M22: =J22*1.1 -> 0
B23: 발주처직불
B24: 현장직불
B25: 직접공사비 계 | E25: =E10+E12+E14+E18+E22 -> 0 | F25: =F10+F12+F14+F18+F22 -> #REF! | G25: =G10+G12+G14+G18+G22 -> 0 | H25: =H10+H12+H14+H18+H22 -> 0 | I25: =I10+I12+I14+I18+I22 -> 0 | J25: =J10+J12+J14+J18+J22 -> #REF! | K25: =K10+K12+K14+K18+K22 -> 0 | M25: =SUM(M10:M22) -> 145670
A26: 현 장 관 리 비 | B26: 복리후생비 | H26: =F26 -> 0 | I26: =H26+G26 -> 0 | K26: =E26+F26 -> 0 | M26: =F26-I26 -> 0
B27: 여비교통비 | H27: =F27 -> 0 | I27: =H27+G27 -> 0 | J27: =F27-I27 -> 0 | K27: =E27+F27 -> 0 | M27: =F27-I27 -> 0
B28: 통신비 | G28: =F28 -> 0 | I28: =H28+G28 -> 0 | J28: =F28-I28 -> 0 | K28: =E28+F28 -> 0 | M28: =F28-I28 -> 0
B29: 소모품비 | I29: =H29+G29 -> 0 | J29: =F29-I29 -> 0 | K29: =E29+F29 -> 0 | M29: =F29-I29 -> 0
B30: 도서인쇄비 | I30: =H30+G30 -> 0 | J30: =F30-I30 -> 0 | K30: =E30+F30 -> 0 | M30: =F30-I30 -> 0
B31: 수선비 | I31: =H31+G31 -> 0 | J31: =F31-I31 -> 0 | K31: =E31+F31 -> 0 | M31: =F31-I31 -> 0
B32: 접대비 | H32: =F32 -> 0 | I32: =H32+G32 -> 0 | J32: =F32-I32 -> 0 | K32: =E32+F32 -> 0 | M32: =F32-I32 -> 0
B33: 야간 경비 | I33: =H33+G33 -> 0 | J33: =F33-I33 -> 0 | K33: =E33+F33 -> 0 | M33: =F33-I33 -> 0
B34: 운반비 | G34: 0 | I34: =H34+G34 -> 0 | J34: =F34-I34 -> 0 | K34: =E34+F34 -> 0 | M34: =F34-I34 -> 0
B35: 기타임차료 | H35: =F35 -> 0 | I35: =H35+G35 -> 0 | J35: =F35-I35 -> 0 | K35: =E35+F35 -> 0 | M35: =F35-I35 -> 0
B36: 차량유지비 | H36: =F36 -> 0 | I36: =H36+G36 -> 0 | J36: =F36-I36 -> 0 | K36: =E36+F36 -> 0 | M36: =F36-I36 -> 0
B37: 출 장 비 | H37: =F37 -> 0 | I37: =H37+G37 -> 0 | J37: =F37-I37 -> 0 | K37: =E37+F37 -> 0 | M37: =F37-I37 -> 0
B38: 현장관리비 | F38: ='업체별지급현황(총괄)'!E10 -> 840500 | J38: =F38-I38 -> 840500 | K38: =E38+F38 -> 840500 | M38: =F38-I38 -> 840500
B39: 잡비 | M39: =F39-I39 -> 0
B40: 예비비 | E40: 0 | I40: =H40+G40 -> 0 | J40: =F40-I40 -> 0 | K40: =E40+F40 -> 0 | M40: =F40-I40 -> 0
B41: 안전 기원제 | I41: =H41+G41 -> 0 | J41: =F41-I41 -> 0 | M41: =F41-I41 -> 0
B42: 준공 | J42: =F42-I42 -> 0 | M42: =F42-I42 -> 0
B43: 직원급료 | I43: =H43+G43 -> 0 | J43: =F43-I43 -> 0 | M43: =F43-I43 -> 0
B44: 직원상여금 | E44: 0 | I44: =H44+G44 -> 0 | J44: =F44-I44 -> 0 | K44: =E44+F44 -> 0 | M44: =F44-I44 -> 0
B45: 임 직 급 여 | J45: =F45-I45 -> 0 | M45: =F45-I45 -> 0
B46: 현장관리비 계 | F46: =SUM(F26:F45) -> 840500 | G46: =SUM(G26:G45) -> 0 | H46: =SUM(H26:H45) -> 0 | I46: =SUM(I26:I45) -> 0 | J46: =SUM(J26:J45) -> 840500 | K46: =SUM(K26:K45) -> 840500 | M46: =F46-I46 -> 840500
...

Sheet 자금청구내역(을)
A1: 자 금 청 구 내 역
A2: =자금청구!A3 -> 현 장 명 : 충북혁신도시 오피스텔 신축공사 | F2: =자금청구!A4 -> 공사기간 : 2014.05.20 ~ 2015.06.30 | J2: (단위:원)
A3: 구 분 | B3: 업 체 명 | C3: 적 요 | E3: 공급가액 | F3: 부가세 | G3: 합 계 | H3: 기지급액 | I3: 본사청구액 | J3: 비 고
A5: 재료비 | B5: =#REF! -> #REF! | C5: =#REF! -> #REF!
B6: =#REF! -> #REF! | C6: =#REF! -> #REF! | E6: =#REF! -> #REF! | F6: =#REF! -> #REF! | G6: =E6+F6 -> #REF! | I6: =G6-H6 -> #REF!
B7: =#REF! -> #REF! | C7: =#REF! -> #REF! | E7: =#REF! -> #REF! | F7: =#REF! -> #REF! | G7: =E7+F7 -> #REF! | I7: =G7-H7 -> #REF!
B8: =#REF! -> #REF! | C8: =#REF! -> #REF! | E8: =#REF! -> #REF! | F8: =#REF! -> #REF! | G8: =E8+F8 -> #REF! | I8: =G8-H8 -> #REF!
B9: =#REF! -> #REF! | C9: =#REF! -> #REF! | E9: =#REF! -> #REF! | F9: =#REF! -> #REF! | G9: =E9+F9 -> #REF! | I9: =G9-H9 -> #REF!
B10: =#REF! -> #REF! | C10: =#REF! -> #REF! | E10: =#REF! -> #REF! | F10: =#REF! -> #REF! | G10: =E10+F10 -> #REF! | I10: =G10-H10 -> #REF!
E11: =#REF! -> #REF! | F11: =#REF! -> #REF! | G11: =E11+F11 -> #REF! | I11: =G11-H11 -> #REF!
E12: =#REF! -> #REF! | F12: =#REF! -> #REF! | G12: =E12+F12 -> #REF! | I12: =G12-H12 -> #REF!
E13: =#REF! -> #REF! | F13: =#REF! -> #REF! | G13: =E13+F13 -> #REF! | I13: =G13-H13 -> #REF!
B14: =#REF! -> #REF! | E14: =#REF! -> #REF! | F14: =#REF! -> #REF! | G14: =E14+F14 -> #REF! | I14: =G14-H14 -> #REF!
B15: =#REF! -> #REF! | F15: =#REF! -> #REF! | G15: =E15+F15 -> #REF! | I15: =G15-H15 -> #REF!
F16: =#REF! -> #REF! | G16: =E16+F16 -> #REF! | I16: =G16-H16 -> #REF!
B17: =#REF! -> #REF! | C17: =#REF! -> #REF! | E17: =#REF! -> #REF! | F17: =#REF! -> #REF! | G17: =E17+F17 -> #REF! | I17: =G17-H17 -> #REF!
B19: 소 계 | E19: =SUM(E5:E17) -> #REF! | F19: =SUM(F5:F17) -> #REF! | G19: =SUM(G5:G17) -> #REF! | H19: =SUM(H5:H17) -> 0 | I19: =SUM(I5:I17) -> #REF!
A20: 노무비
B28: 소 계 | E28: =SUM(E20:E25) -> 0 | F28: =SUM(F20:F25) -> 0 | G28: =SUM(G20:G25) -> 0 | H28: =SUM(H20:H25) -> 0 | I28: =SUM(I20:I25) -> 0 | J28: =SUM(J20:J23) -> 0
A29: 장비비
B43: 소 계 | E43: =SUM(E29:E33) -> 0 | F43: =SUM(F29:F33) -> 0 | G43: =SUM(G29:G33) -> 0 | H43: =SUM(H29:H33) -> 0 | I43: =SUM(I29:I33) -> 0 | J43: 0
A44: 외주비 | B44: =#REF! -> #REF! | C44: =#REF! -> #REF! | E44: =#REF! -> #REF! | F44: =#REF! -> #REF! | G44: =SUM(E44:F44) -> #REF! | H44: 0 | I44: =G44-H44 -> #REF!
B45: =#REF! -> #REF! | C45: =#REF! -> #REF! | E45: =#REF! -> #REF! | F45: =#REF! -> #REF! | G45: =SUM(E45:F45) -> #REF! | H45: 0 | I45: =G45-H45 -> #REF!
B46: =#REF! -> #REF! | C46: =#REF! -> #REF! | E46: =#REF! -> #REF! | F46: =#REF! -> #REF! | G46: =SUM(E46:F46) -> #REF! | H46: 0 | I46: =G46-H46 -> #REF!
B47: =#REF! -> #REF! | C47: =#REF! -> #REF! | E47: =#REF! -> #REF! | F47: =#REF! -> #REF! | G47: =SUM(E47:F47) -> #REF! | H47: 0 | I47: =G47-H47 -> #REF!
B48: =#REF! -> #REF! | C48: =#REF! -> #REF! | E48: =#REF! -> #REF! | F48: =#REF! -> #REF! | G48: =SUM(E48:F48) -> #REF! | H48: 0 | I48: =G48-H48 -> #REF!
B49: =#REF! -> #REF! | C49: =#REF! -> #REF! | E49: =#REF! -> #REF! | F49: =#REF! -> #REF! | G49: =SUM(E49:F49) -> #REF! | H49: 0 | I49: =G49-H49 -> #REF!
B50: =#REF! -> #REF! | C50: =#REF! -> #REF! | E50: =#REF! -> #REF! | F50: =#REF! -> #REF! | G50: =SUM(E50:F50) -> #REF! | H50: 0 | I50: =G50-H50 -> #REF!
B51: =#REF! -> #REF! | C51: =#REF! -> #REF! | E51: =#REF! -> #REF! | F51: =#REF! -> #REF! | G51: =SUM(E51:F51) -> #REF! | H51: 0 | I51: =G51-H51 -> #REF!
B52: =#REF! -> #REF! | C52: =#REF! -> #REF! | E52: =#REF! -> #REF! | F52: =#REF! -> #REF! | G52: =SUM(E52:F52) -> #REF! | H52: 0 | I52: =G52-H52 -> #REF!
B53: =#REF! -> #REF! | C53: =#REF! -> #REF! | E53: =#REF! -> #REF! | F53: =#REF! -> #REF! | G53: =SUM(E53:F53) -> #REF! | H53: 0 | I53: =G53-H53 -> #REF!
B58: 소 계 | E58: =SUM(E44:E57) -> #REF! | F58: =SUM(F44:F57) -> #REF! | G58: =SUM(G44:G57) -> #REF! | H58: =SUM(H44:H57) -> 0 | I58: =SUM(I44:I57) -> #REF! | J58: =SUM(J45:J57) -> 0
B59: =#REF! -> #REF! | C59: =#REF! -> #REF! | E59: =#REF! -> #REF! | F59: =E59*0.1 -> #REF! | G59: =E59+F59 -> #REF! | I59: =G59 -> #REF!
A63: 현장관리비
H65: =H63+H64 -> 0 | I65: =I63+I64 -> 0
B66: 소 계 | E66: =SUM(E59:E65) -> #REF! | F66: =SUM(F59:F65) -> #REF! | G66: =E66+F66 -> #REF! | I66: =SUM(I59:I65) -> #REF!
B67: 전도자금 | C67: 카드
B68: 전도자금 | C68: 현금 | E68: =#REF! -> #REF! | F68: =#REF! -> #REF! | G68: =E68+F68 -> #REF! | H68: =G68 -> #REF!
B69: 전도금 소계 | E69: =E67+E68 -> #REF! | F69: =F67+F68 -> #REF! | G69: =E69+F69 -> #REF! | H69: =SUM(H67:H68) -> #REF!
B70: 소 계 | E70: =E66+E69 -> #REF! | F70: =F66+F69 -> #REF! | G70: =G66+G69 -> #REF! | H70: =G61+G62 -> 0 | I70: =I66+I69 -> #REF!
...

Sheet 업체별지급현황(총괄)
A1: 업 체 별 지 급 현 황
A2: 현 장 명 : 어양중 본관동 강당동 방수공사 및 기타공사
A3: =공사청구!B6 -> 공사기간 : 2024.09.30~2024.11.28
A4: 구 분 | D4: 실행금액 | E4: 11월 | F4: 12월 | P4: 01월 | Q4: 02월 | R4: 3월 | S4: 4월 | T4: 5월 | U4: 합 계
A5: 재 료 비 | D5: =공사청구!H13 -> 1572500 | E5: ='업체별지급현황(재료비)'!E$25 -> 0 | F5: ='업체별지급현황(재료비)'!F$25 -> 2510000 | G5: ='업체별지급현황(재료비)'!G$25 -> 0 | H5: ='업체별지급현황(재료비)'!H$25 -> 0 | I5: ='업체별지급현황(재료비)'!I$25 -> 0 | J5: ='업체별지급현황(재료비)'!J$25 -> 0 | K5: ='업체별지급현황(재료비)'!K$25 -> 0 | L5: ='업체별지급현황(재료비)'!L$25 -> 0 | ... O5: ='업체별지급현황(재료비)'!O$25 -> 0 | U5: =SUM(E5:T5) -> 2510000
A6: 노 무 비 | D6: =공사청구!H14 -> 2206070 | E6: ='업체별지급현황(노무비)'!E25 -> 0 | F6: ='업체별지급현황(노무비)'!F25 -> 0 | G6: ='업체별지급현황(노무비)'!G25 -> 0 | H6: ='업체별지급현황(노무비)'!H25 -> 0 | I6: ='업체별지급현황(노무비)'!I25 -> 0 | J6: ='업체별지급현황(노무비)'!J25 -> 0 | K6: ='업체별지급현황(노무비)'!K25 -> 0 | L6: ='업체별지급현황(노무비)'!L25 -> 0 | ... T6: ='업체별지급현황(노무비)'!T25 -> 0 | U6: =SUM(E6:T6) -> 0
A7: 경 비 | D7: =공사청구!H15 -> 12049769 | E7: ='업체별지급현황(경비)'!E25 -> 0 | F7: ='업체별지급현황(경비)'!F25 -> 0 | G7: ='업체별지급현황(경비)'!G25 -> 0 | H7: ='업체별지급현황(경비)'!H25 -> 0 | I7: ='업체별지급현황(경비)'!I25 -> 0 | J7: ='업체별지급현황(경비)'!J25 -> 0 | K7: ='업체별지급현황(경비)'!K25 -> 0 | L7: ='업체별지급현황(경비)'!L25 -> 0 | ... T7: ='업체별지급현황(경비)'!T25 -> 0 | U7: =SUM(E7:T7) -> 0
A8: 장 비 비 | D8: =공사청구!H16 -> 0 | E8: ='업체별지급현황(장비비)'!E25 -> 0 | F8: ='업체별지급현황(장비비)'!F25 -> 0 | G8: ='업체별지급현황(장비비)'!G25 -> 0 | H8: ='업체별지급현황(장비비)'!H25 -> 0 | I8: ='업체별지급현황(장비비)'!I25 -> 0 | J8: ='업체별지급현황(장비비)'!J25 -> 0 | K8: ='업체별지급현황(장비비)'!K25 -> 0 | L8: ='업체별지급현황(장비비)'!L25 -> 0 | ... T8: ='업체별지급현황(장비비)'!T25 -> 0 | U8: =SUM(E8:T8) -> 0
A9: 외 주 비 | D9: =공사청구!H17 -> 90855500 | E9: ='업체별지급현황(외주비)'!E25 -> 0 | F9: ='업체별지급현황(외주비)'!F25 -> 101505000 | G9: ='업체별지급현황(외주비)'!G25 -> 0 | H9: ='업체별지급현황(외주비)'!H25 -> 0 | I9: ='업체별지급현황(외주비)'!I25 -> 0 | J9: ='업체별지급현황(외주비)'!J25 -> 0 | K9: ='업체별지급현황(외주비)'!K25 -> 0 | L9: ='업체별지급현황(외주비)'!L25 -> 0 | ... O9: ='업체별지급현황(외주비)'!O25 -> 0 | U9: =SUM(E9:T9) -> 101505000
A10: 현장관리비 | D10: =공사청구!H19 -> 1000000 | E10: ='업체별지급현황(현장관리비)'!E29 -> 840500 | F10: ='업체별지급현황(현장관리비)'!F29 -> 350000 | G10: ='업체별지급현황(현장관리비)'!G29 -> 0 | H10: ='업체별지급현황(현장관리비)'!H29 -> 0 | I10: ='업체별지급현황(현장관리비)'!I29 -> 0 | J10: ='업체별지급현황(현장관리비)'!J29 -> 0 | K10: ='업체별지급현황(현장관리비)'!K29 -> 0 | L10: ='업체별지급현황(현장관리비)'!L29 -> 0 | ... O10: ='업체별지급현황(현장관리비)'!O29 -> 0 | U10: =SUM(E10:T10) -> 1190500
A11: 직 원 급 여 | D11: =공사청구!H20 -> 10000000 | E11: 5000000 | F11: 5000000 | U11: =SUM(E11:T11) -> 10000000
A12: 안전+환경+폐기물 | D12: =공사청구!H21 -> 5804361 | E12: ='업체별지급현황(안전,환경,폐기물)'!E25 -> 4395000 | F12: ='업체별지급현황(안전,환경,폐기물)'!F25 -> 650000 | G12: ='업체별지급현황(안전,환경,폐기물)'!G25 -> 0 | H12: ='업체별지급현황(안전,환경,폐기물)'!H25 -> 0 | I12: ='업체별지급현황(안전,환경,폐기물)'!I25 -> 0 | J12: ='업체별지급현황(안전,환경,폐기물)'!J25 -> 0 | K12: ='업체별지급현황(안전,환경,폐기물)'!K25 -> 0 | L12: ='업체별지급현황(안전,환경,폐기물)'!L25 -> 0 | ... O12: ='업체별지급현황(안전,환경,폐기물)'!O25 -> 0 | U12: =SUM(E12:T12) -> 5045000
A13: [소 계] | D13: =SUM(D5:D12) -> 123488200 | E13: =SUM(E5:E12) -> 10235500 | F13: =SUM(F5:F12) -> 110015000 | G13: =SUM(G5:G12) -> 0 | H13: =SUM(H5:H12) -> 0 | I13: =SUM(I5:I12) -> 0 | J13: =SUM(J5:J12) -> 0 | K13: =SUM(K5:K12) -> 0 | ... T13: =SUM(T5:T12) -> 0 | U13: =SUM(E13:T13) -> 120250500
A14: [누 계] | D14: =D13 -> 123488200 | E14: =E13 -> 10235500 | F14: =E14+F13 -> 120250500 | G14: =F14+G13 -> 120250500 | H14: =G14+H13 -> 120250500 | I14: =H14+I13 -> 120250500 | J14: =I14+J13 -> 120250500 | K14: =J14+K13 -> 120250500 | L14: =K14+L13 -> 120250500 | M14: =L14+M13 -> 120250500 | ... T14: =S14+T13 -> 120250500

Sheet 자재비투입원가
A1: 자재비투입원가(7월)원가일보수정본으로 대체
A2: ='업체별지급현황(총괄)'!A2:J2 -> 현 장 명 : 어양중 본관동 강당동 방수공사 및 기타공사
A3: =#REF! -> #REF!
A4: 품 명 / 규 격 | B4: 거래업체 | C4: 반입상황 | S4: 반입량 | T4: 자재단가 | U4: 발생액
C5: 1 | D5: 2 | E5: 3 | F5: 4 | G5: 5 | H5: 6 | I5: 7 | J5: 8 | K5: 9 | L5: 10 | M5: 11 | N5: 12 | O5: 13 | P5: 14 | Q5: 15
C6: 16 | D6: 17 | E6: 18 | F6: 19 | G6: 20 | H6: 21 | I6: 22 | J6: 23 | K6: 24 | L6: 25 | M6: 26 | N6: 27 | O6: 28 | P6: 29 | Q6: 30 | R6: 31
A7: 레미콘(M3) | B7: 한라엔컴 | M7: 3 | S7: =SUM(C7:R8) -> 57 | T7: 58200 | U7: =S7*T7 -> 3317400
A8: 25-180-8 | G8: 54
A9: 레미콘(M3) | S9: =SUM(C9:R10) -> 636 | T9: 64000 | U9: =S9*T9 -> 40704000
A10: 25-27-12 | L10: 636 | V10: =59399200+14505800 -> 73905000
A11: 레미콘(M3) | S11: =SUM(C11:R12) -> 0 | U11: =S11*T11 -> 0
A12: 25-21-120
A13: 레미콘(M3) | S13: =SUM(C13:R14) -> 0 | U13: =S13*T13 -> 0
A15: 레미콘(M3) | S15: =SUM(C15:R16) -> 0 | U15: =S15*T15 -> 0
S17: =SUM(C17:R18) -> 0 | U17: =S17*T17 -> 0
A19: 레미콘(M3) | S19: =SUM(C19:R20) -> 0 | T19: 57900 | U19: =S19*T19 -> 0
A20: 25-18-80 | V20: =59399200+14505800 -> 73905000
A21: 레미콘(M3) | S21: =SUM(C21:R22) -> 0 | T21: 59500 | U21: =S21*T21 -> 0
A22: 25-21-80 | V22: =59399200+14505800 -> 73905000
A23: 레미콘(M3) | S23: =SUM(C23:R24) -> 0 | T23: 61200 | U23: =S23*T23 -> 0
A24: 25-21-120
A25: 레미콘(M3) | S25: =SUM(C25:R26) -> 0 | T25: 61500 | U25: =S25*T25 -> 0
A26: 25-24-80
A27: 레미콘(M3) | S27: =SUM(C27:R28) -> 0 | T27: 65300 | U27: =S27*T27 -> 0
A28: 25-24-150
A29: 몰탈 (M3) | S29: =SUM(C29:R30) -> 0 | T29: 78200 | U29: =S29*T29 -> 0
A30: 1:3
A31: 아스콘표층 | B31: ㈜대주개발 서천공장 | S31: =SUM(C31:R32) -> 0 | T31: 76000 | U31: =S31*T31 -> 0
S33: =SUM(C33:R34) -> 0 | T33: 65300 | U33: =S33*T33 -> 0
S35: =SUM(C35:R36) -> 0 | T35: 78200 | U35: =S35*T35 -> 0
A37: 레미콘(M3) | B37: (유)대신레미콘 | S37: =SUM(C37:R38) -> 0 | T37: 57900 | U37: =S37*T37 -> 0
A38: 25-18-80
A39: 레미콘(M3) | S39: =SUM(C39:R40) -> 0 | T39: 62600 | U39: =S39*T39 -> 0
A40: 25-21-150
A41: 레미콘(M3) | S41: =SUM(C41:R42) -> 0 | T41: 65300 | U41: =S41*T41 -> 0
A42: 25-24-150
A43: 레미콘(M3) | B43: (유)대호레미콘 | S43: =SUM(C43:R44) -> 0 | T43: 62600 | U43: =S43*T43 -> 0
A44: 25-21-150
A45: 소 계 | S45: =SUM(S9:S42) -> 636 | U45: =SUM(U7:U44) -> 44021400
A47: 레미콘(M3) | B47: 오.케이레미콘 | S47: =SUM(C47:R48) -> 0 | T47: =#REF! -> #REF! | U47: =S47*T47 -> #REF!
...

Sheet 임원카드현황
A1: 2020.01월 임원카드 사용 내역 | I1: 결 재 | J1: 담당 | K1: 토목 | L1: 공사 | M1: 안전 | N1: 공무 | O1: 소장
A4: =#REF! -> #REF!
A5: 사용일 | B5: 비목 | C5: 금액 | D5: 거래처 | E5: 내용 | F5: 비 고
A32: 합 계 | C32: =SUM(C7:C31) -> 0
D44: \

Sheet 업체별지급현황(재료비)
A2: 업 체 별 지 급 현 황
A3: ( ■재료비 □노무비 □경비 □장비비 □외주비 □현장관리비 □안전+환경+폐기물 )
B4: 업체명 | C4: 구 분 | D4: 실행금액 | E4: 11월 | F4: 12월 | P4: 9월 | Q4: 10월 | R4: 11월 | S4: 12월 | T4: 01월 | U4: 합 계
A5: 업 체 명 / 금 액 | B5: 신원EPS산업 | C5: 단열재 | D5: 1572500 | F5: 2510000 | U5: =SUM(E5:T5) -> 2510000
U6: =SUM(E6:T6) -> 0
U7: =SUM(E7:T7) -> 0
U8: =SUM(E8:T8) -> 0
U9: =SUM(E9:T9) -> 0
U10: =SUM(E10:T10) -> 0
U11: =SUM(E11:T11) -> 0
U12: =SUM(E12:T12) -> 0
U13: =SUM(E13:T13) -> 0
U14: =SUM(E14:T14) -> 0
U15: =SUM(E15:T15) -> 0
U16: =SUM(E16:T16) -> 0
U17: =SUM(E17:T17) -> 0
... U23: =SUM(E23:T23) -> 0
U24: =SUM(E24:S24) -> 0
A25: [소 계] | D25: =SUM(D5:D24) -> 1572500 | E25: =SUM(E5:E24) -> 0 | F25: =SUM(F5:F24) -> 2510000 | G25: =SUM(G5:G24) -> 0 | H25: =SUM(H5:H24) -> 0 | I25: =SUM(I5:I24) -> 0 | J25: =SUM(J5:J24) -> 0 | K25: =SUM(K5:K24) -> 0 | ... U25: =SUM(U5:U24) -> 2510000
A26: [누 계] | D26: =D25 -> 1572500 | E26: =E25 -> 0 | F26: =E26+F25 -> 2510000 | G26: =F26+G25 -> 2510000 | H26: =G26+H25 -> 2510000 | I26: =H26+I25 -> 2510000 | J26: =I26+J25 -> 2510000 | K26: =J26+K25 -> 2510000 | L26: =K26+L25 -> 2510000 | M26: =L26+M25 -> 2510000 | ... T26: =S26+T25 -> 2510000

Sheet 업체별지급현황(노무비)
A2: 업 체 별 지 급 현 황
A3: ( □재료비 ■노무비 □경비 □장비비 □외주비 □현장관리비 □안전+환경+폐기물 )
B4: 업체명 | C4: 구 분 | D4: 실행금액 | E4: 11월 | F4: 12월 | P4: 9월 | Q4: 10월 | R4: 11월 | S4: 12월 | T4: 01월 | U4: 합 계
A5: 업 체 명 / 금 액 | D5: 2206070 | U5: =SUM(E5:T5) -> 0
U6: =SUM(E6:T6) -> 0
U7: =SUM(E7:T7) -> 0
U8: =SUM(E8:T8) -> 0
U9: =SUM(E9:T9) -> 0
U10: =SUM(E10:T10) -> 0
U11: =SUM(E11:T11) -> 0
U12: =SUM(E12:T12) -> 0
U13: =SUM(E13:T13) -> 0
U14: =SUM(E14:T14) -> 0
U15: =SUM(E15:T15) -> 0
U16: =SUM(E16:T16) -> 0
U17: =SUM(E17:T17) -> 0
... U23: =SUM(E23:T23) -> 0
U24: =SUM(E24:S24) -> 0
A25: [소 계] | D25: =SUM(D5:D24) -> 2206070 | E25: =SUM(E5:E24) -> 0 | F25: =SUM(F5:F24) -> 0 | G25: =SUM(G5:G24) -> 0 | H25: =SUM(H5:H24) -> 0 | I25: =SUM(I5:I24) -> 0 | J25: =SUM(J5:J24) -> 0 | K25: =SUM(K5:K24) -> 0 | ... U25: =SUM(U5:U24) -> 0
A26: [누 계] | D26: =D25 -> 2206070 | E26: =E25 -> 0 | F26: =E26+F25 -> 0 | G26: =F26+G25 -> 0 | H26: =G26+H25 -> 0 | I26: =H26+I25 -> 0 | J26: =I26+J25 -> 0 | K26: =J26+K25 -> 0 | L26: =K26+L25 -> 0 | M26: =L26+M25 -> 0 | ... T26: =S26+T25 -> 0

Sheet 업체별지급현황(경비)
A2: 업 체 별 지 급 현 황
A3: ( □재료비 □노무비 ■경비 □장비비 □외주비 □현장관리비 □안전+환경+폐기물 )
B4: 업체명 | C4: 구 분 | D4: 실행금액 | E4: 11월 | F4: 12월 | P4: 9월 | Q4: 10월 | R4: 11월 | S4: 12월 | T4: 01월 | U4: 합 계
A5: 업 체 명 / 금 액 | D5: 12049769 | U5: =SUM(E5:T5) -> 0
U6: =SUM(E6:T6) -> 0
U7: =SUM(E7:T7) -> 0
U8: =SUM(E8:T8) -> 0
U9: =SUM(E9:T9) -> 0
U10: =SUM(E10:T10) -> 0
U11: =SUM(E11:T11) -> 0
U12: =SUM(E12:T12) -> 0
U13: =SUM(E13:T13) -> 0
U14: =SUM(E14:T14) -> 0
U15: =SUM(E15:T15) -> 0
U16: =SUM(E16:T16) -> 0
U17: =SUM(E17:T17) -> 0
... U23: =SUM(E23:T23) -> 0
U24: =SUM(E24:S24) -> 0
A25: [소 계] | D25: =SUM(D5:D24) -> 12049769 | E25: =SUM(E5:E24) -> 0 | F25: =SUM(F5:F24) -> 0 | G25: =SUM(G5:G24) -> 0 | H25: =SUM(H5:H24) -> 0 | I25: =SUM(I5:I24) -> 0 | J25: =SUM(J5:J24) -> 0 | K25: =SUM(K5:K24) -> 0 | ... U25: =SUM(U5:U24) -> 0
A26: [누 계] | D26: =D25 -> 12049769 | E26: =E25 -> 0 | F26: =E26+F25 -> 0 | G26: =F26+G25 -> 0 | H26: =G26+H25 -> 0 | I26: =H26+I25 -> 0 | J26: =I26+J25 -> 0 | K26: =J26+K25 -> 0 | L26: =K26+L25 -> 0 | M26: =L26+M25 -> 0 | ... T26: =S26+T25 -> 0

Sheet 업체별지급현황(장비비)
A2: 업 체 별 지 급 현 황
A3: ( □재료비 □노무비 □경비 ■장비비 □외주비 □현장관리비 □안전+환경+폐기물 )
B4: 업체명 | C4: 구 분 | D4: 실행금액 | E4: 11월 | F4: 12월 | P4: 9월 | Q4: 10월 | R4: 11월 | S4: 12월 | T4: 01월 | U4: 합 계
A5: 업 체 명 / 금 액 | U5: =SUM(E5:T5) -> 0
U6: =SUM(E6:T6) -> 0
U7: =SUM(E7:T7) -> 0
U8: =SUM(E8:T8) -> 0
U9: =SUM(E9:T9) -> 0
U10: =SUM(E10:T10) -> 0
U11: =SUM(E11:T11) -> 0
U12: =SUM(E12:T12) -> 0
U13: =SUM(E13:T13) -> 0
U14: =SUM(E14:T14) -> 0
U15: =SUM(E15:T15) -> 0
U16: =SUM(E16:T16) -> 0
U17: =SUM(E17:T17) -> 0
... U23: =SUM(E23:T23) -> 0
U24: =SUM(E24:S24) -> 0
A25: [소 계] | D25: =SUM(D5:D24) -> 0 | E25: =SUM(E5:E24) -> 0 | F25: =SUM(F5:F24) -> 0 | G25: =SUM(G5:G24) -> 0 | H25: =SUM(H5:H24) -> 0 | I25: =SUM(I5:I24) -> 0 | J25: =SUM(J5:J24) -> 0 | K25: =SUM(K5:K24) -> 0 | ... U25: =SUM(U5:U24) -> 0
A26: [누 계] | D26: =D25 -> 0 | E26: =E25 -> 0 | F26: =E26+F25 -> 0 | G26: =F26+G25 -> 0 | H26: =G26+H25 -> 0 | I26: =H26+I25 -> 0 | J26: =I26+J25 -> 0 | K26: =J26+K25 -> 0 | L26: =K26+L25 -> 0 | M26: =L26+M25 -> 0 | ... T26: =S26+T25 -> 0

Sheet 업체별지급현황(외주비)
A2: 업 체 별 지 급 현 황
A3: ( □재료비 □노무비 □경비 □장비비 ■외주비 □현장관리비 □안전+환경+폐기물 )
B4: 업체명 | C4: 구 분 | D4: 실행금액 | E4: 11월 | F4: 12월 | P4: 9월 | Q4: 10월 | R4: 11월 | S4: 12월 | T4: 01월 | U4: 합 계
A5: 업 체 명 / 금 액 | B5: 세하디엔씨 | C5: 시트판넬 | D5: 90855500 | F5: 32800000 | U5: =SUM(E5:T5) -> 32800000
B6: 옥석건설 | C6: 적벽돌리노베이션 | F6: 33000000 | U6: =SUM(E6:T6) -> 33000000
B7: (유)해머 | C7: 임목처리 | F7: 300000 | U7: =SUM(E7:T7) -> 300000
B8: ㈜아리울건설 | C8: 옥상방수 | F8: 30000000 | U8: =SUM(E8:T8) -> 30000000
B9: 동창기와건설 | C9: 기와보수 | F9: 600000 | U9: =SUM(E9:T9) -> 600000
B10: ㈜아리울건설 | C10: 옥상방수 | F10: 2605000 | U10: =SUM(E10:T10) -> 2605000
B11: 다사자원 | C11: 철거 | F11: 2200000 | U11: =SUM(E11:T11) -> 2200000
U12: =SUM(E12:T12) -> 0
U13: =SUM(E13:T13) -> 0
U14: =SUM(E14:T14) -> 0
U15: =SUM(E15:T15) -> 0
U16: =SUM(E16:T16) -> 0
U17: =SUM(E17:T17) -> 0
U18: =SUM(E18:T18) -> 0
U19: =SUM(E19:T19) -> 0
U20: =SUM(E20:T20) -> 0
U21: =SUM(E21:T21) -> 0
U22: =SUM(E22:T22) -> 0
U23: =SUM(E23:T23) -> 0
U24: =SUM(E24:S24) -> 0
A25: [소 계] | D25: =SUM(D5:D24) -> 90855500 | E25: =SUM(E5:E24) -> 0 | F25: =SUM(F5:F24) -> 101505000 | G25: =SUM(G5:G24) -> 0 | H25: =SUM(H5:H24) -> 0 | I25: =SUM(I5:I24) -> 0 | J25: =SUM(J5:J24) -> 0 | K25: =SUM(K5:K24) -> 0 | ... U25: =SUM(U5:U24) -> 101505000
A26: [누 계] | D26: =D25 -> 90855500 | E26: =E25 -> 0 | F26: =E26+F25 -> 101505000 | G26: =F26+G25 -> 101505000 | H26: =G26+H25 -> 101505000 | I26: =H26+I25 -> 101505000 | J26: =I26+J25 -> 101505000 | K26: =J26+K25 -> 101505000 | L26: =K26+L25 -> 101505000 | M26: =L26+M25 -> 101505000 | ... T26: =S26+T25 -> 101505000

Sheet 업체별지급현황(현장관리비)
A2: 업 체 별 지 급 현 황
A3: ( □재료비 □노무비 □경비 □장비비 □외주비 ■현장관리비 □안전+환경+폐기물 )
B4: 업체명 | C4: 구 분 | D4: 실행금액 | E4: 11월 | F4: 12월 | P4: 9월 | Q4: 10월 | R4: 11월 | S4: 12월 | T4: 01월 | U4: 합 계
A5: 업 체 명 / 금 액 | B5: ㈜에이텍 | C5: 전자카드단말기 | D5: 1000000 | E5: 220000 | U5: =SUM(E5:T5) -> 220000
B6: 어양중 | C6: 수도광열비 | E6: 270500 | U6: =SUM(E6:T6) -> 270500
U7: =SUM(E7:T7) -> 0
U8: =SUM(E8:T8) -> 0
U9: =SUM(E9:T9) -> 0
U10: =SUM(E10:T10) -> 0
U11: =SUM(E11:T11) -> 0
U12: =SUM(E12:T12) -> 0
U13: =SUM(E13:T13) -> 0
U14: =SUM(E14:T14) -> 0
U15: =SUM(E15:T15) -> 0
U16: =SUM(E16:T16) -> 0
U17: =SUM(E17:T17) -> 0
U18: =SUM(E18:T18) -> 0
... U23: =SUM(E23:T23) -> 0
B24: 계 | D24: =SUM(D5:D23) -> 1000000 | E24: =SUM(E5:E23) -> 490500 | F24: =SUM(F5:F23) -> 0 | G24: =SUM(G5:G23) -> 0 | H24: =SUM(H5:H23) -> 0 | I24: =SUM(I5:I23) -> 0 | J24: =SUM(J5:J23) -> 0 | K24: =SUM(K5:K23) -> 0 | ... U24: =SUM(U5:U23) -> 490500
B25: 전도금 | C25: 현장카드 | E25: 350000 | F25: 350000 | U25: =SUM(E25:T25) -> 700000
C26: 임원카드 | U26: =SUM(E26:T26) -> 0
C27: 현금 | U27: =SUM(E27:T27) -> 0
C28: 계 | D28: =SUM(D25) -> 0 | E28: =SUM(E25:E27) -> 350000 | F28: =SUM(F25:F27) -> 350000 | G28: =SUM(G25:G27) -> 0 | H28: =SUM(H25:H27) -> 0 | I28: =SUM(I25:I27) -> 0 | J28: =SUM(J25:J27) -> 0 | K28: =SUM(K25:K27) -> 0 | L28: =SUM(L25:L27) -> 0 | ... U28: =SUM(U25:U27) -> 700000
A29: [소 계] | D29: =D24+D28 -> 1000000 | E29: =E24+E28 -> 840500 | F29: =F24+F28 -> 350000 | G29: =G24+G28 -> 0 | H29: =H24+H28 -> 0 | I29: =I24+I28 -> 0 | J29: =J24+J28 -> 0 | K29: =K24+K28 -> 0 | ... U29: =U24+U28 -> 1190500
A30: [누 계] | D30: =D29 -> 1000000 | E30: =E29 -> 840500 | F30: =E30+F29 -> 1190500 | G30: =F30+G29 -> 1190500 | H30: =G30+H29 -> 1190500 | I30: =H30+I29 -> 1190500 | J30: =I30+J29 -> 1190500 | K30: =J30+K29 -> 1190500 | L30: =K30+L29 -> 1190500 | M30: =L30+M29 -> 1190500 | ... T30: =S30+T29 -> 1190500

Sheet 업체별지급현황(안전,환경,폐기물)
A2: 업 체 별 지 급 현 황
A3: ( □재료비 □노무비 □경비 □장비비 □외주비 □현장관리비 ■안전+환경+폐기물 )
B4: 업체명 | C4: 구 분 | D4: 실행금액 | E4: 11월 | F4: 12월 | P4: 9월 | Q4: 10월 | R4: 11월 | S4: 12월 | T4: 01월 | U4: 합 계
A5: 업 체 명 / 금 액 | B5: 아리울상사 | C5: 안전화 외 | D5: 5804361 | E5: 4395000 | U5: =SUM(E5:T5) -> 4395000
B6: 코리아환경 | C6: 폐기물 | F6: 650000 | U6: =SUM(E6:T6) -> 650000
U7: =SUM(E7:T7) -> 0
U8: =SUM(E8:T8) -> 0
U9: =SUM(E9:T9) -> 0
U10: =SUM(E10:T10) -> 0
U11: =SUM(E11:T11) -> 0
U12: =SUM(E12:T12) -> 0
U13: =SUM(E13:T13) -> 0
U14: =SUM(E14:T14) -> 0
U15: =SUM(E15:T15) -> 0
U16: =SUM(E16:T16) -> 0
U17: =SUM(E17:T17) -> 0
U18: =SUM(E18:T18) -> 0
... U23: =SUM(E23:T23) -> 0
U24: =SUM(E24:S24) -> 0
A25: [소 계] | D25: =SUM(D5:D24) -> 5804361 | E25: =SUM(E5:E24) -> 4395000 | F25: =SUM(F5:F24) -> 650000 | G25: =SUM(G5:G24) -> 0 | H25: =SUM(H5:H24) -> 0 | I25: =SUM(I5:I24) -> 0 | J25: =SUM(J5:J24) -> 0 | K25: =SUM(K5:K24) -> 0 | ... U25: =SUM(U5:U24) -> 5045000
A26: [누 계] | D26: =D25 -> 5804361 | E26: =E25 -> 4395000 | F26: =E26+F25 -> 5045000 | G26: =F26+G25 -> 5045000 | H26: =G26+H25 -> 5045000 | I26: =H26+I25 -> 5045000 | J26: =I26+J25 -> 5045000 | K26: =J26+K25 -> 5045000 | L26: =K26+L25 -> 5045000 | M26: =L26+M25 -> 5045000 | ... T26: =S26+T25 -> 5045000

Sheet 결재방
B2: 현 장 | C2: 담 당 | D2: 공사 | E2: 공무 | F2: 소 장 | G2: 본 사 | H2: 담 당 | I2: 대 리 | J2: 과 장 | K2: 부 장 | L2: 상 무 | M2: 사 장 | O2: 현 장 | P2: 담 당 | Q2: 차 장 | R2: 소 장 | S2: 소 장 | T2: 본 사 | V2: 담 당 | Z2: 대 리 | AD2: 과 장 | AH2: 부 장 | AL2: 상 무 | AP2: 사 장
B5: 현 장 | C5: 담 당 | D5: 공사 | E5: 공무 | F5: 소 장
B18: 현 장 | C18: 담 당 | E18: 소 장 | F18: 소 장

Sheet 식대 발생현황(예시)
A1: 식대 발생현황 (3월)
A2: 현장명 | B2: 산동지구
A3: 공사명 | B3: 산동지구 다목적 농촌용수 개발사업
A5: 날 짜 | B5: 0 0 식 당(외상 거래) | G5: 카 드 발 생 | L5: 합 계 | M5: 비 고
B6: 조 식 | C6: 중 식 | D6: 석 식 | E6: 회 식 | F6: 계 | G6: 조식 | H6: 중식 | I6: 석식 | J6: 회식 | K6: 계
A7: 43525 | B7: 97500 | C7: 110500 | D7: 97500 | E7: 0 | F7: 305500 | G7: 0 | H7: 0 | I7: 0 | J7: 0 | K7: 0 | L7: 305500
A8: 43526 | B8: 39000 | C8: 52000 | D8: 39000 | E8: 0 | F8: 130000 | G8: 0 | H8: 0 | I8: 0 | J8: 0 | K8: 0 | L8: 130000
A9: 43527 | B9: 0 | C9: 0 | D9: 0 | E9: 0 | F9: 0 | G9: 14000 | H9: 70000 | I9: 36000 | J9: 0 | K9: 120000 | L9: 120000
A10: 43528 | B10: 97500 | C10: 104000 | D10: 91000 | E10: 0 | F10: 292500 | G10: 0 | H10: 0 | I10: 42000 | J10: 0 | K10: 42000 | L10: 334500
A11: 43529 | B11: 97500 | C11: 123500 | D11: 71500 | E11: 0 | F11: 292500 | G11: 0 | H11: 0 | I11: 58900 | J11: 0 | K11: 58900 | L11: 351400
A12: 43530 | B12: 78000 | C12: 104000 | D12: 71500 | E12: 0 | F12: 253500 | G12: 0 | H12: 0 | I12: 33000 | J12: 0 | K12: 33000 | L12: 286500
A13: 43531 | B13: 104000 | C13: 143000 | D13: 104000 | E13: 0 | F13: 351000 | G13: 0 | H13: 0 | I13: 0 | J13: 0 | K13: 0 | L13: 351000
A14: 43532 | B14: 97500 | C14: 136500 | D14: 97500 | E14: 0 | F14: 331500 | G14: 0 | H14: 29000 | I14: 0 | J14: 0 | K14: 29000 | L14: 360500
A15: 43533 | B15: 71500 | C15: 97500 | D15: 71500 | E15: 0 | F15: 240500 | G15: 0 | H15: 0 | I15: 0 | J15: 0 | K15: 0 | L15: 240500
A16: 43534 | B16: 45500 | C16: 26000 | D16: 13000 | E16: 0 | F16: 84500 | G16: 0 | H16: 29000 | I16: 28000 | J16: 0 | K16: 57000 | L16: 141500
A17: 43535 | B17: 71500 | C17: 104000 | D17: 45500 | E17: 0 | F17: 221000 | G17: 0 | H17: 0 | I17: 0 | J17: 209000 | K17: 209000 | L17: 430000
A18: 43536 | B18: 104000 | C18: 123500 | D18: 104000 | E18: 210000 | F18: 541500 | G18: 0 | H18: 31000 | I18: 0 | J18: 0 | K18: 31000 | L18: 572500
... A24: 43542 | B24: 97500 | C24: 117000 | D24: 78000 | E24: 0 | F24: 292500 | G24: 0 | H24: 16000 | I24: 144500 | J24: 0 | K24: 160500 | L24: 453000
A25: 43543 | B25: 91000 | C25: 117000 | D25: 97500 | E25: 0 | F25: 305500 | G25: 9000 | H25: 35000 | J25: 0 | K25: 44000 | L25: 349500
A26: 43544 | B26: 104000 | C26: 123500 | D26: 104000 | E26: 0 | F26: 331500 | G26: 0 | H26: 12000 | I26: 0 | J26: 0 | K26: 12000 | L26: 343500
A27: 43545 | B27: 104000 | C27: 97500 | D27: 91000 | E27: 0 | F27: 292500 | G27: 0 | H27: 35000 | I27: 0 | J27: 0 | K27: 35000 | L27: 327500
A28: 43546 | B28: 110500 | C28: 123500 | D28: 110500 | E28: 0 | F28: 344500 | G28: 0 | H28: 37000 | I28: 0 | J28: 0 | K28: 37000 | L28: 381500
A29: 43547 | B29: 84500 | C29: 97500 | D29: 84500 | E29: 0 | F29: 266500 | G29: 0 | H29: 0 | I29: 0 | J29: 0 | K29: 0 | L29: 266500
A30: 43548 | B30: 84500 | C30: 91000 | D30: 0 | E30: 0 | F30: 175500 | G30: 0 | H30: 92000 | I30: 0 | J30: 0 | K30: 92000 | L30: 267500
A31: 43549 | B31: 91000 | C31: 84500 | D31: 91000 | E31: 0 | F31: 266500 | G31: 0 | H31: 122000 | I31: 0 | J31: 0 | K31: 122000 | L31: 388500
A32: 43550 | B32: 110500 | C32: 130000 | D32: 104000 | E32: 0 | F32: 344500 | G32: 0 | H32: 14000 | I32: 82000 | J32: 0 | K32: 96000 | L32: 440500
A33: 43551 | B33: 110500 | C33: 136500 | D33: 110500 | E33: 0 | F33: 357500 | G33: 0 | H33: 0 | I33: 0 | J33: 0 | K33: 0 | L33: 357500
A34: 43552 | B34: 110500 | C34: 130000 | D34: 110500 | E34: 224000 | F34: 575000 | G34: 0 | H34: 40000 | I34: 0 | J34: 0 | K34: 40000 | L34: 615000
A35: 43553 | B35: 104000 | C35: 136500 | D35: 78000 | E35: 0 | F35: 318500 | G35: 0 | H35: 0 | I35: 33000 | J35: 0 | K35: 33000 | L35: 351500
A36: 43554 | B36: 45500 | C36: 58500 | D36: 32500 | E36: 0 | F36: 136500 | G36: 0 | H36: 0 | I36: 7800 | J36: 0 | K36: 7800 | L36: 144300
A37: 43555 | B37: 0 | C37: 0 | D37: 0 | E37: 0 | F37: 0 | G37: 0 | H37: 23000 | I37: 44000 | J37: 0 | K37: 67000 | L37: 67000
A38: 계 | B38: 8260000 | G38: 1522400 | L38: 9782400
O41: 결 재 | P41: 담 당 | Q41: 소 장
